2023-09-25 15:40:04,347 - ERROR - Exception serializing message!
Traceback (most recent call last):
  File "/home/shivankurtripathi/anaconda3/envs/usermanagement/lib/python3.8/site-packages/grpc/_common.py", line 89, in _transform
    return transformer(message)
TypeError: descriptor 'SerializeToString' for 'google.protobuf.pyext._message.CMessage' objects doesn't apply to a 'NoneType' object
2023-09-25 16:21:23,144 - ERROR - Exception calling application: 'platformRequest' object is not subscriptable
Traceback (most recent call last):
  File "/home/shivankurtripathi/anaconda3/envs/usermanagement/lib/python3.8/site-packages/grpc/_server.py", line 552, in _call_behavior
    response_or_iterator = behavior(argument, context)
  File "/home/shivankurtripathi/Desktop/workspace/DataNext/src/python/social/oculus_user_management/server.py", line 44, in addPlatform
    if request['platform_name']=='facebook':
TypeError: 'platformRequest' object is not subscriptable
2023-09-25 16:21:54,351 - ERROR - Exception calling application: 'platformRequest' object is not subscriptable
Traceback (most recent call last):
  File "/home/shivankurtripathi/anaconda3/envs/usermanagement/lib/python3.8/site-packages/grpc/_server.py", line 552, in _call_behavior
    response_or_iterator = behavior(argument, context)
  File "/home/shivankurtripathi/Desktop/workspace/DataNext/src/python/social/oculus_user_management/server.py", line 44, in addPlatform
    if request['platform_name']=='facebook':
TypeError: 'platformRequest' object is not subscriptable
2023-09-25 16:22:59,136 - ERROR - Exception calling application: 'platform_name'
Traceback (most recent call last):
  File "/home/shivankurtripathi/anaconda3/envs/usermanagement/lib/python3.8/site-packages/grpc/_server.py", line 552, in _call_behavior
    response_or_iterator = behavior(argument, context)
  File "/home/shivankurtripathi/Desktop/workspace/DataNext/src/python/social/oculus_user_management/server.py", line 45, in addPlatform
    if request['platform_name']=='facebook':
KeyError: 'platform_name'
2023-09-25 16:41:33,024 - ERROR - Exception serializing message!
Traceback (most recent call last):
  File "/home/shivankurtripathi/anaconda3/envs/usermanagement/lib/python3.8/site-packages/grpc/_common.py", line 89, in _transform
    return transformer(message)
TypeError: descriptor 'SerializeToString' for 'google.protobuf.pyext._message.CMessage' objects doesn't apply to a 'NoneType' object
2023-09-25 16:43:29,307 - ERROR - Exception calling application: Invalid URL 'https: // graph.facebook.com/110928107339307': No host supplied
Traceback (most recent call last):
  File "/home/shivankurtripathi/anaconda3/envs/usermanagement/lib/python3.8/site-packages/grpc/_server.py", line 552, in _call_behavior
    response_or_iterator = behavior(argument, context)
  File "/home/shivankurtripathi/Desktop/workspace/DataNext/src/python/social/oculus_user_management/server.py", line 46, in addPlatform
    SocialConnectors.FaceBook(**request['data']).register_connector()
  File "/home/shivankurtripathi/Desktop/workspace/DataNext/src/python/social/oculus_user_management/connectors/SocialConnectors.py", line 10, in register_connector
    return self.__request_connector(params=self.__get_user_fields(),type='GET')
  File "/home/shivankurtripathi/Desktop/workspace/DataNext/src/python/social/oculus_user_management/connectors/SocialConnectors.py", line 20, in __request_connector
    return requests.get(url=URL,params=params)
  File "/home/shivankurtripathi/anaconda3/envs/usermanagement/lib/python3.8/site-packages/requests/api.py", line 73, in get
    return request("get", url, params=params, **kwargs)
  File "/home/shivankurtripathi/anaconda3/envs/usermanagement/lib/python3.8/site-packages/requests/api.py", line 59, in request
    return session.request(method=method, url=url, **kwargs)
  File "/home/shivankurtripathi/anaconda3/envs/usermanagement/lib/python3.8/site-packages/requests/sessions.py", line 575, in request
    prep = self.prepare_request(req)
  File "/home/shivankurtripathi/anaconda3/envs/usermanagement/lib/python3.8/site-packages/requests/sessions.py", line 486, in prepare_request
    p.prepare(
  File "/home/shivankurtripathi/anaconda3/envs/usermanagement/lib/python3.8/site-packages/requests/models.py", line 368, in prepare
    self.prepare_url(url, params)
  File "/home/shivankurtripathi/anaconda3/envs/usermanagement/lib/python3.8/site-packages/requests/models.py", line 445, in prepare_url
    raise InvalidURL(f"Invalid URL {url!r}: No host supplied")
requests.exceptions.InvalidURL: Invalid URL 'https: // graph.facebook.com/110928107339307': No host supplied
2023-09-25 16:50:09,477 - ERROR - Exception calling application: 'FaceBook' object has no attribute 'access_token'
Traceback (most recent call last):
  File "/home/shivankurtripathi/anaconda3/envs/usermanagement/lib/python3.8/site-packages/grpc/_server.py", line 552, in _call_behavior
    response_or_iterator = behavior(argument, context)
  File "/home/shivankurtripathi/Desktop/workspace/DataNext/src/python/social/oculus_user_management/server.py", line 46, in addPlatform
    SocialConnectors.FaceBook(**request['data']).register_connector()
  File "/home/shivankurtripathi/Desktop/workspace/DataNext/src/python/social/oculus_user_management/connectors/SocialConnectors.py", line 10, in register_connector
    return self.__request_connector(params=self.__get_user_fields(),type='GET')
  File "/home/shivankurtripathi/Desktop/workspace/DataNext/src/python/social/oculus_user_management/connectors/SocialConnectors.py", line 23, in __request_connector
    URL+'&fields ='+params+'& access_token='+self.access_token
AttributeError: 'FaceBook' object has no attribute 'access_token'
2023-09-25 16:53:05,979 - ERROR - Exception calling application: 'FaceBook' object has no attribute 'access_token'
Traceback (most recent call last):
  File "/home/shivankurtripathi/anaconda3/envs/usermanagement/lib/python3.8/site-packages/grpc/_server.py", line 552, in _call_behavior
    response_or_iterator = behavior(argument, context)
  File "/home/shivankurtripathi/Desktop/workspace/DataNext/src/python/social/oculus_user_management/server.py", line 46, in addPlatform
    SocialConnectors.FaceBook(**request['data']).register_connector()
  File "/home/shivankurtripathi/Desktop/workspace/DataNext/src/python/social/oculus_user_management/connectors/SocialConnectors.py", line 10, in register_connector
    return self.__request_connector(params=self.__get_user_fields(),type='GET')
  File "/home/shivankurtripathi/Desktop/workspace/DataNext/src/python/social/oculus_user_management/connectors/SocialConnectors.py", line 23, in __request_connector
    URL=URL+'&fields ='+params+'& access_token='+self.accesstoken
AttributeError: 'FaceBook' object has no attribute 'access_token'
2023-09-26 10:17:48,323 - ERROR - Exception calling application: 3 validation errors for FaceBook
platform_name
  field required (type=value_error.missing)
registration_time
  field required (type=value_error.missing)
last_updated_time
  field required (type=value_error.missing)
Traceback (most recent call last):
  File "/home/shivankurtripathi/anaconda3/envs/usermanagement/lib/python3.8/site-packages/grpc/_server.py", line 552, in _call_behavior
    response_or_iterator = behavior(argument, context)
  File "/home/shivankurtripathi/Desktop/workspace/DataNext/src/python/social/oculus_user_management/server.py", line 46, in addPlatform
    SocialConnectors.FaceBook(**request).register_connector()
  File "pydantic/main.py", line 341, in pydantic.main.BaseModel.__init__
pydantic.error_wrappers.ValidationError: 3 validation errors for FaceBook
platform_name
  field required (type=value_error.missing)
registration_time
  field required (type=value_error.missing)
last_updated_time
  field required (type=value_error.missing)
2023-09-26 10:19:00,268 - ERROR - Exception calling application: 3 validation errors for FaceBook
platform_name
  field required (type=value_error.missing)
registration_time
  field required (type=value_error.missing)
last_updated_time
  field required (type=value_error.missing)
Traceback (most recent call last):
  File "/home/shivankurtripathi/anaconda3/envs/usermanagement/lib/python3.8/site-packages/grpc/_server.py", line 552, in _call_behavior
    response_or_iterator = behavior(argument, context)
  File "/home/shivankurtripathi/Desktop/workspace/DataNext/src/python/social/oculus_user_management/server.py", line 46, in addPlatform
    SocialConnectors.FaceBook(**request).register_connector()
  File "pydantic/main.py", line 341, in pydantic.main.BaseModel.__init__
pydantic.error_wrappers.ValidationError: 3 validation errors for FaceBook
platform_name
  field required (type=value_error.missing)
registration_time
  field required (type=value_error.missing)
last_updated_time
  field required (type=value_error.missing)
2023-09-26 10:33:34,859 - ERROR - Exception calling application: 'FaceBook' object has no attribute 'appId'
Traceback (most recent call last):
  File "/home/shivankurtripathi/anaconda3/envs/usermanagement/lib/python3.8/site-packages/grpc/_server.py", line 552, in _call_behavior
    response_or_iterator = behavior(argument, context)
  File "/home/shivankurtripathi/Desktop/workspace/DataNext/src/python/social/oculus_user_management/server.py", line 46, in addPlatform
    SocialConnectors.FaceBook(**request).register_connector()
  File "/home/shivankurtripathi/Desktop/workspace/DataNext/src/python/social/oculus_user_management/connectors/SocialConnectors.py", line 12, in register_connector
    return self.__request_connector(params=self.__get_user_fields(),type='GET')
  File "/home/shivankurtripathi/Desktop/workspace/DataNext/src/python/social/oculus_user_management/connectors/SocialConnectors.py", line 22, in __request_connector
    URL="https: // graph.facebook.com/v16.0/?"+self.appId
AttributeError: 'FaceBook' object has no attribute 'appId'
2023-09-26 10:39:06,183 - ERROR - Exception calling application: 'FaceBook' object has no attribute 'appId'
Traceback (most recent call last):
  File "/home/shivankurtripathi/anaconda3/envs/usermanagement/lib/python3.8/site-packages/grpc/_server.py", line 552, in _call_behavior
    response_or_iterator = behavior(argument, context)
  File "/home/shivankurtripathi/Desktop/workspace/DataNext/src/python/social/oculus_user_management/server.py", line 46, in addPlatform
    SocialConnectors.FaceBook(**request).register_connector()
  File "/home/shivankurtripathi/Desktop/workspace/DataNext/src/python/social/oculus_user_management/connectors/SocialConnectors.py", line 12, in register_connector
    return self.__request_connector(params=self.__get_user_fields(),type='GET')
  File "/home/shivankurtripathi/Desktop/workspace/DataNext/src/python/social/oculus_user_management/connectors/SocialConnectors.py", line 22, in __request_connector
    URL="https: // graph.facebook.com/v16.0/?"+self.appId
AttributeError: 'FaceBook' object has no attribute 'appId'
2023-09-26 10:40:10,903 - ERROR - Exception calling application: Invalid URL 'https: // graph.facebook.com/v16.0/?110928107339307&fields=id,name,accounts{name,about,global_brand_page_name,access_token,category,connected_instagram_account,fan_count,features,followers_count,genre,has_whatsapp_business_number,instagram_business_account,business,tasks},business_users{first_name,id,last_name,business,assigned_pages{name,global_brand_page_name,category,id,access_token,connected_instagram_account,followers_count,has_whatsapp_business_number,instagram_business_account,permitted_tasks,tasks}}& access_token=EAADp0kuQjd0BOZC4Wt3O9JGrDUbh6876jokgpR62hJuWoXHJW5jtyGbSh7uO2tTvjaWFvzkZBt6jWLLEZBrwA5Iyb5PpSMlEJ37b7qT7pTtWLHoBlfU6RpoFKxnRz8sea24aaw7LA8xh1yWTcVcqjLdaJ3mFoY6MZCM0xmTlxBX5yI387XDIcJrLxShvafYbZAfnH7ynGudR5QLXK0x7TEZCZBc': No host supplied
Traceback (most recent call last):
  File "/home/shivankurtripathi/anaconda3/envs/usermanagement/lib/python3.8/site-packages/grpc/_server.py", line 552, in _call_behavior
    response_or_iterator = behavior(argument, context)
  File "/home/shivankurtripathi/Desktop/workspace/DataNext/src/python/social/oculus_user_management/server.py", line 46, in addPlatform
    SocialConnectors.FaceBook(**request).register_connector()
  File "/home/shivankurtripathi/Desktop/workspace/DataNext/src/python/social/oculus_user_management/connectors/SocialConnectors.py", line 12, in register_connector
    return self.__request_connector(params=self.__get_user_fields(),type='GET')
  File "/home/shivankurtripathi/Desktop/workspace/DataNext/src/python/social/oculus_user_management/connectors/SocialConnectors.py", line 25, in __request_connector
    return requests.get(url=URL)
  File "/home/shivankurtripathi/anaconda3/envs/usermanagement/lib/python3.8/site-packages/requests/api.py", line 73, in get
    return request("get", url, params=params, **kwargs)
  File "/home/shivankurtripathi/anaconda3/envs/usermanagement/lib/python3.8/site-packages/requests/api.py", line 59, in request
    return session.request(method=method, url=url, **kwargs)
  File "/home/shivankurtripathi/anaconda3/envs/usermanagement/lib/python3.8/site-packages/requests/sessions.py", line 575, in request
    prep = self.prepare_request(req)
  File "/home/shivankurtripathi/anaconda3/envs/usermanagement/lib/python3.8/site-packages/requests/sessions.py", line 486, in prepare_request
    p.prepare(
  File "/home/shivankurtripathi/anaconda3/envs/usermanagement/lib/python3.8/site-packages/requests/models.py", line 368, in prepare
    self.prepare_url(url, params)
  File "/home/shivankurtripathi/anaconda3/envs/usermanagement/lib/python3.8/site-packages/requests/models.py", line 445, in prepare_url
    raise InvalidURL(f"Invalid URL {url!r}: No host supplied")
requests.exceptions.InvalidURL: Invalid URL 'https: // graph.facebook.com/v16.0/?110928107339307&fields=id,name,accounts{name,about,global_brand_page_name,access_token,category,connected_instagram_account,fan_count,features,followers_count,genre,has_whatsapp_business_number,instagram_business_account,business,tasks},business_users{first_name,id,last_name,business,assigned_pages{name,global_brand_page_name,category,id,access_token,connected_instagram_account,followers_count,has_whatsapp_business_number,instagram_business_account,permitted_tasks,tasks}}& access_token=EAADp0kuQjd0BOZC4Wt3O9JGrDUbh6876jokgpR62hJuWoXHJW5jtyGbSh7uO2tTvjaWFvzkZBt6jWLLEZBrwA5Iyb5PpSMlEJ37b7qT7pTtWLHoBlfU6RpoFKxnRz8sea24aaw7LA8xh1yWTcVcqjLdaJ3mFoY6MZCM0xmTlxBX5yI387XDIcJrLxShvafYbZAfnH7ynGudR5QLXK0x7TEZCZBc': No host supplied
2023-09-26 12:01:50,944 - ERROR - Exception calling application: HTTPSConnectionPool(host='graph.facebook.com', port=443): Max retries exceeded with url: /v16.0/944195206818903?fields=id,name,accounts%7Bname,about,global_brand_page_name,access_token,category,connected_instagram_account,fan_count,features,followers_count,genre,has_whatsapp_business_number,instagram_business_account,business,tasks%7D,business_users%7Bfirst_name,id,last_name,business,assigned_pages%7Bname,global_brand_page_name,category,id,access_token,connected_instagram_account,followers_count,has_whatsapp_business_number,instagram_business_account,permitted_tasks,tasks%7D%7D&%20access_token=EAADp0kuQjd0BOwf9do7EqXpDU7KB87yRZAGB5bJnxfZBkoZB5UKmG4SL0ZBMeBMOTWqn7dCf0zAxzHrLbSod5qWZAJl9EYOZAhoUP7BZBmnmitRmMe4AYlgMpp2ffcfs498aFyeZA7ns5JISEGMbGu4ugc5gHLosb9jLsGitfUGJGzaD9ASGvObI0CQzrRhHkHxNoRnAHfZBduXAdoFKIZCwZDZD (Caused by NameResolutionError("<urllib3.connection.HTTPSConnection object at 0x7f67242ffdf0>: Failed to resolve 'graph.facebook.com' ([Errno -3] Temporary failure in name resolution)"))
Traceback (most recent call last):
  File "/home/shivankurtripathi/anaconda3/envs/usermanagement/lib/python3.8/site-packages/urllib3/connection.py", line 200, in _new_conn
    sock = connection.create_connection(
  File "/home/shivankurtripathi/anaconda3/envs/usermanagement/lib/python3.8/site-packages/urllib3/util/connection.py", line 60, in create_connection
    for res in socket.getaddrinfo(host, port, family, socket.SOCK_STREAM):
  File "/home/shivankurtripathi/anaconda3/envs/usermanagement/lib/python3.8/socket.py", line 918, in getaddrinfo
    for res in _socket.getaddrinfo(host, port, family, type, proto, flags):
socket.gaierror: [Errno -3] Temporary failure in name resolution

The above exception was the direct cause of the following exception:

Traceback (most recent call last):
  File "/home/shivankurtripathi/anaconda3/envs/usermanagement/lib/python3.8/site-packages/urllib3/connectionpool.py", line 790, in urlopen
    response = self._make_request(
  File "/home/shivankurtripathi/anaconda3/envs/usermanagement/lib/python3.8/site-packages/urllib3/connectionpool.py", line 491, in _make_request
    raise new_e
  File "/home/shivankurtripathi/anaconda3/envs/usermanagement/lib/python3.8/site-packages/urllib3/connectionpool.py", line 467, in _make_request
    self._validate_conn(conn)
  File "/home/shivankurtripathi/anaconda3/envs/usermanagement/lib/python3.8/site-packages/urllib3/connectionpool.py", line 1092, in _validate_conn
    conn.connect()
  File "/home/shivankurtripathi/anaconda3/envs/usermanagement/lib/python3.8/site-packages/urllib3/connection.py", line 604, in connect
    self.sock = sock = self._new_conn()
  File "/home/shivankurtripathi/anaconda3/envs/usermanagement/lib/python3.8/site-packages/urllib3/connection.py", line 207, in _new_conn
    raise NameResolutionError(self.host, self, e) from e
urllib3.exceptions.NameResolutionError: <urllib3.connection.HTTPSConnection object at 0x7f67242ffdf0>: Failed to resolve 'graph.facebook.com' ([Errno -3] Temporary failure in name resolution)

The above exception was the direct cause of the following exception:

Traceback (most recent call last):
  File "/home/shivankurtripathi/anaconda3/envs/usermanagement/lib/python3.8/site-packages/requests/adapters.py", line 486, in send
    resp = conn.urlopen(
  File "/home/shivankurtripathi/anaconda3/envs/usermanagement/lib/python3.8/site-packages/urllib3/connectionpool.py", line 844, in urlopen
    retries = retries.increment(
  File "/home/shivankurtripathi/anaconda3/envs/usermanagement/lib/python3.8/site-packages/urllib3/util/retry.py", line 515, in increment
    raise MaxRetryError(_pool, url, reason) from reason  # type: ignore[arg-type]
urllib3.exceptions.MaxRetryError: HTTPSConnectionPool(host='graph.facebook.com', port=443): Max retries exceeded with url: /v16.0/944195206818903?fields=id,name,accounts%7Bname,about,global_brand_page_name,access_token,category,connected_instagram_account,fan_count,features,followers_count,genre,has_whatsapp_business_number,instagram_business_account,business,tasks%7D,business_users%7Bfirst_name,id,last_name,business,assigned_pages%7Bname,global_brand_page_name,category,id,access_token,connected_instagram_account,followers_count,has_whatsapp_business_number,instagram_business_account,permitted_tasks,tasks%7D%7D&%20access_token=EAADp0kuQjd0BOwf9do7EqXpDU7KB87yRZAGB5bJnxfZBkoZB5UKmG4SL0ZBMeBMOTWqn7dCf0zAxzHrLbSod5qWZAJl9EYOZAhoUP7BZBmnmitRmMe4AYlgMpp2ffcfs498aFyeZA7ns5JISEGMbGu4ugc5gHLosb9jLsGitfUGJGzaD9ASGvObI0CQzrRhHkHxNoRnAHfZBduXAdoFKIZCwZDZD (Caused by NameResolutionError("<urllib3.connection.HTTPSConnection object at 0x7f67242ffdf0>: Failed to resolve 'graph.facebook.com' ([Errno -3] Temporary failure in name resolution)"))

During handling of the above exception, another exception occurred:

Traceback (most recent call last):
  File "/home/shivankurtripathi/anaconda3/envs/usermanagement/lib/python3.8/site-packages/grpc/_server.py", line 552, in _call_behavior
    response_or_iterator = behavior(argument, context)
  File "/home/shivankurtripathi/Desktop/workspace/DataNext/src/python/social/oculus_user_management/server.py", line 46, in addPlatform
    SocialConnectors.FaceBook(**request).register_connector()
  File "/home/shivankurtripathi/Desktop/workspace/DataNext/src/python/social/oculus_user_management/connectors/SocialConnectors.py", line 12, in register_connector
    return self.__request_connector(params=self.__get_user_fields(),type='GET')
  File "/home/shivankurtripathi/Desktop/workspace/DataNext/src/python/social/oculus_user_management/connectors/SocialConnectors.py", line 25, in __request_connector
    return requests.get(url=URL)
  File "/home/shivankurtripathi/anaconda3/envs/usermanagement/lib/python3.8/site-packages/requests/api.py", line 73, in get
    return request("get", url, params=params, **kwargs)
  File "/home/shivankurtripathi/anaconda3/envs/usermanagement/lib/python3.8/site-packages/requests/api.py", line 59, in request
    return session.request(method=method, url=url, **kwargs)
  File "/home/shivankurtripathi/anaconda3/envs/usermanagement/lib/python3.8/site-packages/requests/sessions.py", line 589, in request
    resp = self.send(prep, **send_kwargs)
  File "/home/shivankurtripathi/anaconda3/envs/usermanagement/lib/python3.8/site-packages/requests/sessions.py", line 703, in send
    r = adapter.send(request, **kwargs)
  File "/home/shivankurtripathi/anaconda3/envs/usermanagement/lib/python3.8/site-packages/requests/adapters.py", line 519, in send
    raise ConnectionError(e, request=request)
requests.exceptions.ConnectionError: HTTPSConnectionPool(host='graph.facebook.com', port=443): Max retries exceeded with url: /v16.0/944195206818903?fields=id,name,accounts%7Bname,about,global_brand_page_name,access_token,category,connected_instagram_account,fan_count,features,followers_count,genre,has_whatsapp_business_number,instagram_business_account,business,tasks%7D,business_users%7Bfirst_name,id,last_name,business,assigned_pages%7Bname,global_brand_page_name,category,id,access_token,connected_instagram_account,followers_count,has_whatsapp_business_number,instagram_business_account,permitted_tasks,tasks%7D%7D&%20access_token=EAADp0kuQjd0BOwf9do7EqXpDU7KB87yRZAGB5bJnxfZBkoZB5UKmG4SL0ZBMeBMOTWqn7dCf0zAxzHrLbSod5qWZAJl9EYOZAhoUP7BZBmnmitRmMe4AYlgMpp2ffcfs498aFyeZA7ns5JISEGMbGu4ugc5gHLosb9jLsGitfUGJGzaD9ASGvObI0CQzrRhHkHxNoRnAHfZBduXAdoFKIZCwZDZD (Caused by NameResolutionError("<urllib3.connection.HTTPSConnection object at 0x7f67242ffdf0>: Failed to resolve 'graph.facebook.com' ([Errno -3] Temporary failure in name resolution)"))
2023-09-26 12:02:55,776 - ERROR - Exception calling application: HTTPSConnectionPool(host='graph.facebook.com', port=443): Max retries exceeded with url: /v16.0/944195206818903?fields=id,name,accounts%7Bname,about,global_brand_page_name,access_token,category,connected_instagram_account,fan_count,features,followers_count,genre,has_whatsapp_business_number,instagram_business_account,business,tasks%7D,business_users%7Bfirst_name,id,last_name,business,assigned_pages%7Bname,global_brand_page_name,category,id,access_token,connected_instagram_account,followers_count,has_whatsapp_business_number,instagram_business_account,permitted_tasks,tasks%7D%7D&%20access_token=EAADp0kuQjd0BOwf9do7EqXpDU7KB87yRZAGB5bJnxfZBkoZB5UKmG4SL0ZBMeBMOTWqn7dCf0zAxzHrLbSod5qWZAJl9EYOZAhoUP7BZBmnmitRmMe4AYlgMpp2ffcfs498aFyeZA7ns5JISEGMbGu4ugc5gHLosb9jLsGitfUGJGzaD9ASGvObI0CQzrRhHkHxNoRnAHfZBduXAdoFKIZCwZDZD (Caused by NameResolutionError("<urllib3.connection.HTTPSConnection object at 0x7ff2846fd640>: Failed to resolve 'graph.facebook.com' ([Errno -3] Temporary failure in name resolution)"))
Traceback (most recent call last):
  File "/home/shivankurtripathi/anaconda3/envs/usermanagement/lib/python3.8/site-packages/urllib3/connection.py", line 200, in _new_conn
    sock = connection.create_connection(
  File "/home/shivankurtripathi/anaconda3/envs/usermanagement/lib/python3.8/site-packages/urllib3/util/connection.py", line 60, in create_connection
    for res in socket.getaddrinfo(host, port, family, socket.SOCK_STREAM):
  File "/home/shivankurtripathi/anaconda3/envs/usermanagement/lib/python3.8/socket.py", line 918, in getaddrinfo
    for res in _socket.getaddrinfo(host, port, family, type, proto, flags):
socket.gaierror: [Errno -3] Temporary failure in name resolution

The above exception was the direct cause of the following exception:

Traceback (most recent call last):
  File "/home/shivankurtripathi/anaconda3/envs/usermanagement/lib/python3.8/site-packages/urllib3/connectionpool.py", line 790, in urlopen
    response = self._make_request(
  File "/home/shivankurtripathi/anaconda3/envs/usermanagement/lib/python3.8/site-packages/urllib3/connectionpool.py", line 491, in _make_request
    raise new_e
  File "/home/shivankurtripathi/anaconda3/envs/usermanagement/lib/python3.8/site-packages/urllib3/connectionpool.py", line 467, in _make_request
    self._validate_conn(conn)
  File "/home/shivankurtripathi/anaconda3/envs/usermanagement/lib/python3.8/site-packages/urllib3/connectionpool.py", line 1092, in _validate_conn
    conn.connect()
  File "/home/shivankurtripathi/anaconda3/envs/usermanagement/lib/python3.8/site-packages/urllib3/connection.py", line 604, in connect
    self.sock = sock = self._new_conn()
  File "/home/shivankurtripathi/anaconda3/envs/usermanagement/lib/python3.8/site-packages/urllib3/connection.py", line 207, in _new_conn
    raise NameResolutionError(self.host, self, e) from e
urllib3.exceptions.NameResolutionError: <urllib3.connection.HTTPSConnection object at 0x7ff2846fd640>: Failed to resolve 'graph.facebook.com' ([Errno -3] Temporary failure in name resolution)

The above exception was the direct cause of the following exception:

Traceback (most recent call last):
  File "/home/shivankurtripathi/anaconda3/envs/usermanagement/lib/python3.8/site-packages/requests/adapters.py", line 486, in send
    resp = conn.urlopen(
  File "/home/shivankurtripathi/anaconda3/envs/usermanagement/lib/python3.8/site-packages/urllib3/connectionpool.py", line 844, in urlopen
    retries = retries.increment(
  File "/home/shivankurtripathi/anaconda3/envs/usermanagement/lib/python3.8/site-packages/urllib3/util/retry.py", line 515, in increment
    raise MaxRetryError(_pool, url, reason) from reason  # type: ignore[arg-type]
urllib3.exceptions.MaxRetryError: HTTPSConnectionPool(host='graph.facebook.com', port=443): Max retries exceeded with url: /v16.0/944195206818903?fields=id,name,accounts%7Bname,about,global_brand_page_name,access_token,category,connected_instagram_account,fan_count,features,followers_count,genre,has_whatsapp_business_number,instagram_business_account,business,tasks%7D,business_users%7Bfirst_name,id,last_name,business,assigned_pages%7Bname,global_brand_page_name,category,id,access_token,connected_instagram_account,followers_count,has_whatsapp_business_number,instagram_business_account,permitted_tasks,tasks%7D%7D&%20access_token=EAADp0kuQjd0BOwf9do7EqXpDU7KB87yRZAGB5bJnxfZBkoZB5UKmG4SL0ZBMeBMOTWqn7dCf0zAxzHrLbSod5qWZAJl9EYOZAhoUP7BZBmnmitRmMe4AYlgMpp2ffcfs498aFyeZA7ns5JISEGMbGu4ugc5gHLosb9jLsGitfUGJGzaD9ASGvObI0CQzrRhHkHxNoRnAHfZBduXAdoFKIZCwZDZD (Caused by NameResolutionError("<urllib3.connection.HTTPSConnection object at 0x7ff2846fd640>: Failed to resolve 'graph.facebook.com' ([Errno -3] Temporary failure in name resolution)"))

During handling of the above exception, another exception occurred:

Traceback (most recent call last):
  File "/home/shivankurtripathi/anaconda3/envs/usermanagement/lib/python3.8/site-packages/grpc/_server.py", line 552, in _call_behavior
    response_or_iterator = behavior(argument, context)
  File "/home/shivankurtripathi/Desktop/workspace/DataNext/src/python/social/oculus_user_management/server.py", line 46, in addPlatform
    SocialConnectors.FaceBook(**request).register_connector()
  File "/home/shivankurtripathi/Desktop/workspace/DataNext/src/python/social/oculus_user_management/connectors/SocialConnectors.py", line 12, in register_connector
    return self.__request_connector(params=self.__get_user_fields(),type='GET')
  File "/home/shivankurtripathi/Desktop/workspace/DataNext/src/python/social/oculus_user_management/connectors/SocialConnectors.py", line 25, in __request_connector
    return requests.get(url=URL)
  File "/home/shivankurtripathi/anaconda3/envs/usermanagement/lib/python3.8/site-packages/requests/api.py", line 73, in get
    return request("get", url, params=params, **kwargs)
  File "/home/shivankurtripathi/anaconda3/envs/usermanagement/lib/python3.8/site-packages/requests/api.py", line 59, in request
    return session.request(method=method, url=url, **kwargs)
  File "/home/shivankurtripathi/anaconda3/envs/usermanagement/lib/python3.8/site-packages/requests/sessions.py", line 589, in request
    resp = self.send(prep, **send_kwargs)
  File "/home/shivankurtripathi/anaconda3/envs/usermanagement/lib/python3.8/site-packages/requests/sessions.py", line 703, in send
    r = adapter.send(request, **kwargs)
  File "/home/shivankurtripathi/anaconda3/envs/usermanagement/lib/python3.8/site-packages/requests/adapters.py", line 519, in send
    raise ConnectionError(e, request=request)
requests.exceptions.ConnectionError: HTTPSConnectionPool(host='graph.facebook.com', port=443): Max retries exceeded with url: /v16.0/944195206818903?fields=id,name,accounts%7Bname,about,global_brand_page_name,access_token,category,connected_instagram_account,fan_count,features,followers_count,genre,has_whatsapp_business_number,instagram_business_account,business,tasks%7D,business_users%7Bfirst_name,id,last_name,business,assigned_pages%7Bname,global_brand_page_name,category,id,access_token,connected_instagram_account,followers_count,has_whatsapp_business_number,instagram_business_account,permitted_tasks,tasks%7D%7D&%20access_token=EAADp0kuQjd0BOwf9do7EqXpDU7KB87yRZAGB5bJnxfZBkoZB5UKmG4SL0ZBMeBMOTWqn7dCf0zAxzHrLbSod5qWZAJl9EYOZAhoUP7BZBmnmitRmMe4AYlgMpp2ffcfs498aFyeZA7ns5JISEGMbGu4ugc5gHLosb9jLsGitfUGJGzaD9ASGvObI0CQzrRhHkHxNoRnAHfZBduXAdoFKIZCwZDZD (Caused by NameResolutionError("<urllib3.connection.HTTPSConnection object at 0x7ff2846fd640>: Failed to resolve 'graph.facebook.com' ([Errno -3] Temporary failure in name resolution)"))
2023-09-26 12:04:50,331 - ERROR - Exception serializing message!
Traceback (most recent call last):
  File "/home/shivankurtripathi/anaconda3/envs/usermanagement/lib/python3.8/site-packages/grpc/_common.py", line 89, in _transform
    return transformer(message)
TypeError: descriptor 'SerializeToString' for 'google.protobuf.pyext._message.CMessage' objects doesn't apply to a 'NoneType' object
2023-09-26 12:54:42,100 - ERROR - Exception serializing message!
Traceback (most recent call last):
  File "/home/shivankurtripathi/anaconda3/envs/usermanagement/lib/python3.8/site-packages/grpc/_common.py", line 89, in _transform
    return transformer(message)
TypeError: descriptor 'SerializeToString' for 'google.protobuf.pyext._message.CMessage' objects doesn't apply to a 'NoneType' object
2023-09-26 13:15:56,107 - ERROR - Exception serializing message!
Traceback (most recent call last):
  File "/home/shivankurtripathi/anaconda3/envs/usermanagement/lib/python3.8/site-packages/grpc/_common.py", line 89, in _transform
    return transformer(message)
TypeError: descriptor 'SerializeToString' for 'google.protobuf.pyext._message.CMessage' objects doesn't apply to a 'NoneType' object
2023-09-27 17:18:21,971 - ERROR - Exception calling application: update_one() missing 1 required positional argument: 'self'
Traceback (most recent call last):
  File "/home/shivankurtripathi/anaconda3/envs/usermanagement/lib/python3.8/site-packages/grpc/_server.py", line 552, in _call_behavior
    response_or_iterator = behavior(argument, context)
  File "/home/shivankurtripathi/Desktop/workspace/DataNext/src/python/social/oculus_user_management/server.py", line 46, in addPlatform
    return usermanagement_pb2.platformResponce(media_responce=SocialConnectors.FaceBook(**request).register_connector())
  File "/home/shivankurtripathi/Desktop/workspace/DataNext/src/python/social/oculus_user_management/connectors/SocialConnectors.py", line 15, in register_connector
    if(datasource.Mongo.update_one(id=self.registrationId,document=json.loads(self.json(exclude={'registrationId'})))):
TypeError: update_one() missing 1 required positional argument: 'self'
2023-09-27 17:47:28,777 - ERROR - Exception calling application: '{"registrationId": "OCULUS827612530", "platformName": "facebook", "data": {"id": "944195206818903", has type str, but expected one of: int, bool
Traceback (most recent call last):
  File "/home/shivankurtripathi/anaconda3/envs/usermanagement/lib/python3.8/site-packages/grpc/_server.py", line 552, in _call_behavior
    response_or_iterator = behavior(argument, context)
  File "/home/shivankurtripathi/Desktop/workspace/DataNext/src/python/social/oculus_user_management/server.py", line 46, in addPlatform
    return usermanagement_pb2.platformResponce(media_responce=SocialConnectors.FaceBook(**request).register_connector())
TypeError: '{"registrationId": "OCULUS827612530", "platformName": "facebook", "data": {"id": "944195206818903", has type str, but expected one of: int, bool
2023-09-27 17:50:13,461 - ERROR - Exception calling application: '{"registrationId": "OCULUS827612530", "platformName": "facebook", "data": {"id": "944195206818903", has type str, but expected one of: int, bool
Traceback (most recent call last):
  File "/home/shivankurtripathi/anaconda3/envs/usermanagement/lib/python3.8/site-packages/grpc/_server.py", line 552, in _call_behavior
    response_or_iterator = behavior(argument, context)
  File "/home/shivankurtripathi/Desktop/workspace/DataNext/src/python/social/oculus_user_management/server.py", line 46, in addPlatform
    return usermanagement_pb2.platformResponce(media_responce=SocialConnectors.FaceBook(**request).register_connector())
TypeError: '{"registrationId": "OCULUS827612530", "platformName": "facebook", "data": {"id": "944195206818903", has type str, but expected one of: int, bool
2023-09-27 17:55:47,069 - ERROR - Exception calling application: '{"registrationId": "OCULUS827612530", "platformName": "facebook", "data": {"id": "944195206818903", has type str, but expected one of: int, bool
Traceback (most recent call last):
  File "/home/shivankurtripathi/anaconda3/envs/usermanagement/lib/python3.8/site-packages/grpc/_server.py", line 552, in _call_behavior
    response_or_iterator = behavior(argument, context)
  File "/home/shivankurtripathi/Desktop/workspace/DataNext/src/python/social/oculus_user_management/server.py", line 46, in addPlatform
    return usermanagement_pb2.platformResponce(media_responce=SocialConnectors.FaceBook(**request).register_connector())
TypeError: '{"registrationId": "OCULUS827612530", "platformName": "facebook", "data": {"id": "944195206818903", has type str, but expected one of: int, bool
2023-09-27 17:56:27,104 - ERROR - Exception calling application: '{"registrationId": "OCULUS827612530", "platformName": "facebook", "data": {"id": "944195206818903", has type str, but expected one of: int, bool
Traceback (most recent call last):
  File "/home/shivankurtripathi/anaconda3/envs/usermanagement/lib/python3.8/site-packages/grpc/_server.py", line 552, in _call_behavior
    response_or_iterator = behavior(argument, context)
  File "/home/shivankurtripathi/Desktop/workspace/DataNext/src/python/social/oculus_user_management/server.py", line 46, in addPlatform
    return usermanagement_pb2.platformResponce(media_responce=SocialConnectors.FaceBook(**request).register_connector())
TypeError: '{"registrationId": "OCULUS827612530", "platformName": "facebook", "data": {"id": "944195206818903", has type str, but expected one of: int, bool
2023-09-27 17:58:03,016 - ERROR - Exception calling application: '{"registrationId": "OCULUS1387905081", "platformName": "facebook", "data": {"id": "944195206818903" has type str, but expected one of: int, bool
Traceback (most recent call last):
  File "/home/shivankurtripathi/anaconda3/envs/usermanagement/lib/python3.8/site-packages/grpc/_server.py", line 552, in _call_behavior
    response_or_iterator = behavior(argument, context)
  File "/home/shivankurtripathi/Desktop/workspace/DataNext/src/python/social/oculus_user_management/server.py", line 46, in addPlatform
    return usermanagement_pb2.platformResponce(media_responce=SocialConnectors.FaceBook(**request).register_connector())
TypeError: '{"registrationId": "OCULUS1387905081", "platformName": "facebook", "data": {"id": "944195206818903" has type str, but expected one of: int, bool
2023-09-27 18:00:04,011 - ERROR - Exception calling application: '{"registrationId": "OCULUS1387905081", "platformName": "facebook", "data": {"id": "944195206818903" has type str, but expected one of: int, bool
Traceback (most recent call last):
  File "/home/shivankurtripathi/anaconda3/envs/usermanagement/lib/python3.8/site-packages/grpc/_server.py", line 552, in _call_behavior
    response_or_iterator = behavior(argument, context)
  File "/home/shivankurtripathi/Desktop/workspace/DataNext/src/python/social/oculus_user_management/server.py", line 46, in addPlatform
    return usermanagement_pb2.platformResponce(media_responce=SocialConnectors.FaceBook(**request).register_connector())
TypeError: '{"registrationId": "OCULUS1387905081", "platformName": "facebook", "data": {"id": "944195206818903" has type str, but expected one of: int, bool
2023-09-28 10:46:42,217 - ERROR - Exception calling application: '{"registrationId": "OCULUS1387905081", "platformName": "facebook", "data": {"error": {"message": "E has type str, but expected one of: int, bool
Traceback (most recent call last):
  File "/home/shivankurtripathi/anaconda3/envs/usermanagement/lib/python3.8/site-packages/grpc/_server.py", line 552, in _call_behavior
    response_or_iterator = behavior(argument, context)
  File "/home/shivankurtripathi/Desktop/workspace/DataNext/src/python/social/oculus_user_management/server.py", line 46, in addPlatform
    return usermanagement_pb2.platformResponce(media_responce=SocialConnectors.FaceBook(**request).register_connector())
TypeError: '{"registrationId": "OCULUS1387905081", "platformName": "facebook", "data": {"error": {"message": "E has type str, but expected one of: int, bool
